Workbook

Sheet AMORT
A1: WATERGARDEN MANAGEMENT S.à r.l. | G1: Situation au | H1: 46022
A2: AMORTISSEMENTS
A6: FRAIS AUGMENTATION DE CAPITAL ET TRANSFORMATIONS | C6: $2030000 | D6: Tx 20% | F6: =DAYS360(B8,F7) -> 135 | G6: =DAYS360(F7,G7) -> 360 | H6: =DAYS360(G7,H7) -> 360 | I6: =DAYS360(H7,I7) -> 360 | J6: =DAYS360(I7,J7) -> 360 | K6: =DAYS360(J7,K7) -> 225
A7: FRAIS AUGMENTATION DE CAPITAL | B7: Periode amortissement 5 ANS | E7: Montant | F7: 43465 | G7: 43830 | H7: 44196 | I7: 44561 | J7: 44926 | K7: 45153
A8: ME SCHAEFFER NO 1804091 | B8: 43328 | C8: 45153 | D8: =DAYS360(B8,$F$7) -> 135 | E8: 1723.58 | F8: =-E8*20%*F6/360-18.32 -> -147.5885 | G8: =-E8*20%*G6/360 -> -344.716 | H8: =-$E8*20%*H6/360 -> -344.716 | I8: =-$E8*20%*I6/360 -> -344.716 | J8: =-$E8*20%*J6/360 -> -344.716 | K8: =-$E8*20%*K6/360+18.32 -> -197.1275 | L8: =SUM(E8:K8) -> -3.126388e-13
A9: htva 1 723.58€ | L9: =SUM(E9:K9) -> 0
A10: tva 242.52€ | L10: =SUM(E10:K10) -> 0
B11: dans les comptes de reprises, une erreure de compte avait été faite lors de la déduction du montant de TVA de la facture
B12: en 2019 un ajustement de 94.93€ a été passé du compte $2039 au $2031
A14: FRAIS AUGMENTATION DE CAPITAL ET TRANSFORMATIONS | C14: $2030000 | D14: Tx 20% | F14: =DAYS360(B16,F15) -> 14 | G14: =DAYS360(F15,G15) -> 360 | H14: =DAYS360(G15,H15) -> 360 | I14: =DAYS360(H15,I15) -> 360 | J14: =DAYS360(I15,J15) -> 360 | K14: =DAYS360(J15,K15) -> 346
A15: FRAIS DE FUSION | B15: Periode amortissement 5 ANS | E15: Montant | F15: 44561 | G15: 44926 | H15: 45291 | I15: 45657 | J15: 46022 | K15: 46372
A16: ME Joëlle BADEN - TTC 3 839.03€ | B16: 44547 | C16: 46372 | D16: =DAYS360(B16,$F$15) -> 14 | E16: 3326.83 | F16: =-$E$16*F14*20%/360 -> -25.875344 | G16: =-$E$16*G14*20%/360 -> -665.366 | H16: =-$E$16*H14*20%/360 -> -665.366 | I16: =-$E$16*I14*20%/360 -> -665.366 | J16: =-$E$16*J14*20%/360 -> -665.366 | K16: =-$E$16*K14*20%/360 -> -639.49066 | L16: =SUM(E16:K16) -> 0
A17: ESSEDI PARTNERS - TTC 2 925€ | B17: 44547 | C17: 46372 | D17: =DAYS360(B17,$F$15) -> 14 | E17: 2500 | F17: =-$E$17*F14*20%/360 -> -19.444444 | G17: =-$E$17*G14*20%/360 -> -500 | H17: =-$E$17*H14*20%/360 -> -500 | I17: =-$E$17*I14*20%/360 -> -500 | J17: =-$E$17*J14*20%/360 -> -500 | K17: =-$E$17*K14*20%/360 -> -480.55556 | L17: =SUM(E17:K17) -> 0
L18: =SUM(E18:K18) -> 0
A21: FRAIS AUGMENTATION DE CAPITAL ET TRANSFORMATIONS | C21: $2030000 | D21: Tx 20% | F21: =DAYS360(B23,F22) -> 294 | G21: =DAYS360(F22,G22) -> 360 | H21: =DAYS360(G22,H22) -> 360 | I21: =DAYS360(H22,I22) -> 360 | J21: =DAYS360(I22,J22) -> 360 | K21: =DAYS360(J22,K22) -> 66
A22: FRAIS AUGMENTATION DE CAPITAL | B22: Periode amortissement 5 ANS | E22: Montant | F22: 44926 | G22: =F22+365 -> 45291 | H22: =G22+366 -> 45657 | I22: =H22+365 -> 46022 | J22: =I22+365 -> 46387 | K22: 46452
A23: ME SCHAEFFER N°2200954 | B23: 44627 | C23: 46452 | D23: =DAYS360(B23,F22) -> 294 | E23: 62.55 | F23: =-E23*20%*D23/360 -> -10.2165 | G23: =-E23*20%*G21/360 -> -12.51 | H23: =-$E23*20%*H21/360 -> -12.51 | I23: =-$E23*20%*I21/360 -> -12.51 | J23: =-$E23*20%*J21/360 -> -12.51 | K23: =-$E23*20%*K21/360 -> -2.2935 | L23: =SUM(E23:K23) -> -8.8817842e-15
F26: =DAYS360(B28,F27) -> 11 | G26: =DAYS360(F27,G27) -> 360 | H26: =DAYS360(G27,H27) -> 360 | I26: =DAYS360(H27,I27) -> 360 | J26: =DAYS360(I27,J27) -> 360 | K26: =DAYS360(J27,K27) -> 360 | L26: =DAYS360(K27,L27) -> 360
A27: FRAIS AUGMENTATION DE CAPITAL | B27: Periode amortissement 5 ANS | E27: Montant | F27: 44926 | G27: =F27+365 -> 45291 | H27: =G27+366 -> 45657 | I27: =H27+365 -> 46022 | J27: =I27+365 -> 46387 | K27: 46752 | L27: 47118
A28: Me Joëlle BADEN fte n° 5964 421260/22 | B28: 44915 | C28: 46740 | D28: =DAYS360(B28,F27) -> 11 | E28: 1205.75 | F28: =-$E$28*20%*D28/360 -> -7.3684722 | G28: =-$E$28*20%*G26/360 -> -241.15 | H28: =-$E$28*20%*H26/360 -> -241.15 | I28: =-$E$28*20%*I26/360 -> -241.15 | J28: =-$E$28*20%*J26/360 -> -241.15 | K28: =-$E$28*20%*(K26-D28)/360 -> -233.78153 | M28: =SUM(E28:L28) -> 0
A29: Essedi Partners ttc 1 740€ | B29: 45084 | C29: 46911 | D29: =DAYS360(B29,$G$27) -> 204 | E29: 1500 | G29: =-$E$29*20%*D29/360 -> -170 | H29: =-$E$29*20%*H26/360 -> -300 | I29: =-$E$29*20%*I26/360 -> -300 | J29: =-$E$29*20%*J26/360 -> -300 | K29: =-$E$29*20%*K26/360 -> -300 | L29: =-$E$29*20%*(L26-D29)/360 -> -130 | M29: =SUM(E29:L29) -> 0
B31: Total | E31: =+E8+E16+E17+E23+E28+E29 -> 10318.71 | F31: =+F8+F16+F17+F23+F28+F29 -> -210.49326 | G31: =+G8+G16+G17+G23+G28+G29 -> -1933.742 | H31: =+H8+H16+H17+H23+H28+H29 -> -2063.742 | I31: =+I8+I16+I17+I23+I28+I29 -> -2063.742 | J31: =+J8+J16+J17+J23+J28+J29 -> -2063.742 | K31: =+K8+K16+K17+K23+K28+K29 -> -1853.2487 | L31: =+L8+L16+L17+L23+L28+L29 -> -130 | M31: =SUM(E31:L31) -> -1.6768809e-12
A32: $2039 | C32: total amortissement | D32: ex précédents | E32: =+F8+G8+H8+I8+J8+F16+G16+F17+G17+F23+F28-0.02+K8+H16+H17+G23+G28+G29+I16+I17+H23+H28+H29 -> -6259.9228
A33: $6311 | C33: total amortissement | D33: =+H1 -> 46022 | E33: =+J16+J17+I23+I28+I29 -> -1719.026
C34: solde au | D34: =+H1 -> 46022 | E34: =+E31+E32+E33 -> 2339.7612

Sheet PARTICIP
A1: WATERGARDEN MANAGEMENT S.à r.l. | G1: Situation au | H1: =AMORT!H1 -> 46022
A2: PARTICIPATIONS
A5: ARCO-IRIS ADMINISTRADORA DE BENS E IMOVEIS LTDA, Brazil
A6: Date | B6: Capital en BRL | C6: Nbre actions | D6: Valeur nominale | E6: Nominal détenu | F6: Pourcentage de détention | G6: Montant payé en EUR | H6: Solde payé en EUR | J6: Autres actionnaires | K6: Nbre actions | L6: Valeur nominale | M6: Nominal détenu | N6: Pourcentage détention
B7: 13184044 | C7: 13184044 | D7: 1 | E7: =+C7*D7 -> 13184044 | F7: =+E7/B7 -> 1 | G7: 4774300 | H7: =+G7 -> 4774300 | J7: Franco Toscano | K7: =10000000-10000-3320000-3330000 -> 3340000 | L7: 0.01 | M7: =+K7*L7 -> 33400 | N7: =+M7/B17 -> 0.0030407744
A8: 43102 | B8: 13184044 | E8: =+E7+C8*D8 -> 13184044 | F8: =+E8/B8 -> 1 | G8: 1214200 | H8: =+H7+G8 -> 5988500 | J8: Goyanna Participacoes e Acessoria Empresarial Ltda | K8: =10000+3320000 -> 3330000 | L8: 0.01 | M8: =+K8*L8 -> 33300 | N8: =+M8/B17 -> 0.0030316703
E9: régularisation augm capital du 30/04/2015 par conversion financement
A11: Réduc de val + réd capital + aj détention | J11: J.M. EMPREENDIMENTOS IMOBILIARIOS E HOTELEIROS LTDA | K11: =10000+3320000 -> 3330000 | L11: 0.01 | M11: =+K11*L11 -> 33300 | N11: =+M11/B17 -> 0.0030316703
A12: 44490 | B12: =+B8 -> 13184044 | C12: 1318404400 | D12: 0.01 | E12: =C12*D12 -> 13184044 | F12: =+E12/B12 -> 1 | H12: =+H8+G12 -> 5988500
A13: 44490 | B13: =+B12-2700000 -> 10484044 | C13: -270000000 | D13: 0.01 | E13: =+E12+C13*D13 -> 10484044 | F13: =+E13/B13 -> 1 | G13: =+(C13*D13)/5.56*0.86176+0.01 -> -418480.57 | H13: =+H12+G13 -> 5570019.4
A14: 44490 | B14: =+B13 -> 10484044 | C14: -10000000 | D14: 0.01 | E14: =+E13+C14*D14 -> 10384044 | F14: =+E14/B14 -> 0.9904617 | H14: =+H13+G14 -> 5570019.4
A15: 44490 | B15: =+B14 -> 10484044 | D15: 0.01 | E15: =+E14+C15*D15 -> 10384044 | F15: =+E15/B15 -> 0.9904617 | H15: =+H14+G15 -> 5570019.4
A16: Augm capital - 500.000 BRL
A17: 44931 | B17: =+B15+500000 -> 10984044 | C17: 50000000 | D17: 0.01 | E17: =+E15+C17*D17 -> 10884044 | F17: =+E17/B17 -> 0.99089588 | G17: 87627.06 | H17: =+H15+G17 -> 5657646.5
A20: TOTAL | H20: =+H17 -> 5657646.5 | N20: =SUM(N7:N18) -> 0.009104115 | O20: =+F17+N20 -> 1
M24: tx 31/12/24
J25: Résultat 2023 – 12.696,82 R$
J26: P&L cumulé : - 4.349.513,36 R$ (inclus 2023)
J27: cap propres | K27: 6623682.5 | M27: =+K27*'LOAN ARCO IRIS'!M17 -> 1030876.8
J28: rés 2023 | K28: -12696.82 | M28: =+K28*'LOAN ARCO IRIS'!M17 -> -1976.0696
B31: TOTAL IM. FIN | C31: =+H20+'LOAN ARCO IRIS'!D32 -> 6205953.4

Sheet LOAN ARCO IRIS
A1: WATERGARDEN MANAGEMENT S.à r.l. | F1: Situation au | G1: 46022
A2: FINANCEMENTS ACCORDES
C5: Financement ARCO -IRIS ADMINISTRADORA DE BENS E IMOVEIS LTDA
C6: 0% et ensuite 7% à partir du 15/12/2021
A7: Date | C7: Tranche BRL | D7: Montant en EUR | E7: Taux d'intérêt | H7: Intérêts courus BRL 2022 | I7: Intérêts courus EUR 2022 | J7: Intérêts courus BRL 2023 | K7: Intérêts courus EUR 2023 | L7: Intérêts courus BRL 2024 | M7: Intérêts courus EUR 2024 | N7: Intérêts courus BRL 2025 | O7: Intérêts courus EUR 2025
A8: 44242 | H8: tx 31/12 /22 | I8: 5.63 | J8: tx 31/12 /23 | K8: 5.3618 | L8: tx 31/12 /24 | M8: 0.155635 | N8: tx 31/12 /25 | O8: =1/6.436 -> 0.15537601
A9: $232200001 | B9: Giorgio Vignolle | C9: 135482.33 | D9: 29826.31 | E9: 0.07 | H9: 9483.76 | I9: =+H9/I$8 -> 1684.5044 | J9: 10147.63 | K9: =+J9/K$8 -> 1892.579 | L9: 10857.96 | M9: =+L9*M$8 -> 1689.8786 | N9: =+C9*E9 -> 9483.7631 | O9: =+N9*O$8 -> 1473.5493 | P9: $41112508 | Q9: =+F9+H9+J9+L9+N9 -> 39973.113 | R9: =+G9+I9+K9+M9+O9 -> 6740.5113 | S9: Giorgio Vignolle
A10: $232200002 | B10: Edoardo Tubia | C10: 454237.67 | D10: 100000 | E10: 0.07 | H10: 31796.64 | I10: =+H10/I$8 -> 5647.7158 | J10: 34022.4 | K10: =+J10/K$8 -> 6345.3318 | L10: 36403.97 | M10: =+L10*M$8 -> 5665.7319 | N10: =+C10*E10 -> 31796.637 | O10: =+N10*O$8 -> 4940.4346 | P10: $41112509 | Q10: =+F10+H10+J10+L10+N10 -> 134019.65 | R10: =+G10+I10+K10+M10+O10 -> 22599.214 | S10: Edoardo Tubia
C11: =SUM(C9:C10) -> 589720 | D11: =SUM(D9:D10) -> 129826.31 | H11: =SUM(H9:H10) -> 41280.4 | I11: =SUM(I9:I10) -> 7332.2202 | J11: =SUM(J9:J10) -> 44170.03 | K11: =SUM(K9:K10) -> 8237.9108 | L11: =SUM(L9:L10) -> 47261.93 | M11: =SUM(M9:M10) -> 7355.6105 | N11: =SUM(N9:N10) -> 41280.4 | O11: =SUM(O9:O10) -> 6413.9838 | Q11: =SUM(Q9:Q10) -> 173992.76 | R11: =SUM(R9:R10) -> 29339.725
C14: Financement ARCO -IRIS ADMINISTRADORA DE BENS E IMOVEIS LTDA
C15: 0% et ensuite 7% à partir du 01/01/2022
A16: Date | C16: Tranche BRL | D16: Montant en EUR | E16: Taux d'intérêt | F16: Intérêts courus BRL 2021 | G16: Intérêts courus EUR 2021 | H16: Intérêts courus BRL 2022 | I16: Intérêts courus EUR 2022 | J16: Intérêts courus BRL 2023 | K16: Intérêts courus EUR 2023 | L16: Intérêts courus BRL 2024 | M16: Intérêts courus EUR 2024 | N16: Intérêts courus BRL 2025 | O16: Intérêts courus EUR 2025
A17: 44490 | F17: tx 31/12 /21 | G17: 6.3100961 | H17: tx 31/12 /22 | I17: 5.63 | J17: tx 31/12 /23 | K17: 5.3618 | L17: tx 31/12 /24 | M17: 0.155635 | N17: tx 31/12 /25 | O17: =1/6.436 -> 0.15537601
B18: Alfonso Belardi | C18: 0 | D18: 0 | E18: 0.07 | F18: =+C18*E18*0.0444444444444444 -> 0 | G18: =+F18/G$17 -> 0 | H18: 0 | I18: =+H18/I$8 -> 0 | J18: =+C18*E18 -> 0 | K18: =+J18/K$8 -> 0 | L18: =+C18*E18 -> 0 | M18: =+L18*M$8 -> 0 | N18: =+$C18*$E18 -> 0 | O18: =+N18*O$8 -> 0 | P18: $41112501 | Q18: =+F18+H18+J18+L18+N18 -> 0 | R18: =+G18+I18+K18+M18+O18 -> 0 | S18: Alfonso Belardi
A19: $232100002 | B19: Sergio Vandi | C19: 311059.91 | D19: 48212.05 | E19: 0.07 | F19: =+C19*E19*0.0444444444444444 -> 967.74194 | G19: =+F19/G$17 -> 153.36406 | H19: 21955.65 | I19: =+H19/I$8 -> 3899.7602 | J19: =+C19*E19 -> 21774.194 | K19: =+J19/K$8 -> 4060.9858 | L19: =+C19*E19 -> 21774.194 | M19: =+L19*M$8 -> 3388.8266 | N19: =+$C19*$E19 -> 21774.194 | O19: =+N19*O$8 -> 3383.1873 | P19: $41112502 | Q19: =+F19+H19+J19+L19+N19 -> 88245.973 | R19: =+G19+I19+K19+M19+O19 -> 14886.124 | S19: Sergio Vandi
A20: $232100003 | B20: J-P Murgia | C20: 21774.19 | D20: 3374.84 | E20: 0.07 | F20: =+C20*E20*0.0444444444444444 -> 67.741924 | G20: =+F20/G$17 -> 10.735482 | H20: 1536.9 | I20: =+H20/I$8 -> 272.98401 | J20: =+C20*E20 -> 1524.1933 | K20: =+J20/K$8 -> 284.26896 | L20: =+C20*E20 -> 1524.1933 | M20: =+L20*M$8 -> 237.21782 | N20: =+$C20*$E20 -> 1524.1933 | O20: =+N20*O$8 -> 236.82307 | P20: $41112503 | Q20: =+F20+H20+J20+L20+N20 -> 6177.2218 | R20: =+G20+I20+K20+M20+O20 -> 1042.0294 | S20: J-P Murgia
A21: $232100004 | B21: Stéphane Bosi | C21: 248847.93 | D21: 38569.64 | E21: 0.07 | F21: =+C21*E21*0.0444444444444444 -> 774.19356 | G21: =+F21/G$17 -> 122.69125 | H21: 17564.52 | I21: =+H21/I$8 -> 3119.8082 | J21: =+C21*E21 -> 17419.355 | K21: =+J21/K$8 -> 3248.7887 | L21: =+C21*E21 -> 17419.355 | M21: =+L21*M$8 -> 2711.0613 | N21: =+$C21*$E21 -> 17419.355 | O21: =+N21*O$8 -> 2706.5499 | P21: $41112504 | Q21: =+F21+H21+J21+L21+N21 -> 70596.779 | R21: =+G21+I21+K21+M21+O21 -> 11908.899 | S21: Stéphane Bosi
A22: $232100005 | B22: Marco Canton | C22: 186635.94 | D22: 28927.23 | E22: 0.07 | F22: =+C22*E22*0.0444444444444444 -> 580.64515 | G22: =+F22/G$17 -> 92.018431 | H22: 13173.39 | I22: =+H22/I$8 -> 2339.8561 | J22: =+C22*E22 -> 13064.516 | K22: =+J22/K$8 -> 2436.5914 | L22: =+C22*E22 -> 13064.516 | M22: =+L22*M$8 -> 2033.2959 | N22: =+$C22*$E22 -> 13064.516 | O22: =+N22*O$8 -> 2029.9123 | P22: $41112505 | Q22: =+F22+H22+J22+L22+N22 -> 52947.583 | R22: =+G22+I22+K22+M22+O22 -> 8931.6742 | S22: Marco Canton
A23: $232100006 | B23: Susik Hemawiti | C23: 71543.78 | D23: 11088.77 | E23: 0.07 | F23: =+C23*E23*0.0444444444444444 -> 222.58065 | G23: =+F23/G$17 -> 35.273733 | H23: 5049.8 | I23: =+H23/I$8 -> 896.94494 | J23: =+C23*E23 -> 5008.0646 | K23: =+J23/K$8 -> 934.02674 | L23: =+C23*E23 -> 5008.0646 | M23: =+L23*M$8 -> 779.43013 | N23: =+$C23*$E23 -> 5008.0646 | O23: =+N23*O$8 -> 778.1331 | P23: $41112506 | Q23: =+F23+H23+J23+L23+N23 -> 20296.574 | R23: =+G23+I23+K23+M23+O23 -> 3423.8086 | S23: Susik Hemawiti
A24: $232100007 | B24: Marco Sterzi | C24: 423041.47 | D24: 65568.38 | E24: 0.07 | F24: =+C24*E24*0.0444444444444444 -> 1316.129 | G24: =+F24/G$17 -> 208.57511 | H24: 29859.68 | I24: =+H24/I$8 -> 5303.6732 | J24: =+C24*E24 -> 29612.903 | K24: =+J24/K$8 -> 5522.9406 | L24: =+C24*E24 -> 29612.903 | M24: =+L24*M$8 -> 4608.8041 | N24: =+$C24*$E24 -> 29612.903 | O24: =+N24*O$8 -> 4601.1347 | P24: $41112507 | Q24: =+F24+H24+J24+L24+N24 -> 120014.52 | R24: =+G24+I24+K24+M24+O24 -> 20245.128 | S24: Marco Sterzi
A25: $232100008 | B25: Giorgio Vignolle | C25: 171082.95 | D25: 26516.63 | E25: 0.07 | F25: =+C25*E25*0.0444444444444444 -> 532.25807 | G25: =+F25/G$17 -> 84.350231 | H25: 12075.6 | I25: =+H25/I$8 -> 2144.8668 | J25: =+C25*E25 -> 11975.807 | K25: =+J25/K$8 -> 2233.5422 | L25: =+C25*E25 -> 11975.807 | M25: =+L25*M$8 -> 1863.8546 | N25: =+$C25*$E25 -> 11975.807 | O25: =+N25*O$8 -> 1860.753 | P25: $41112508 | Q25: =+F25+H25+J25+L25+N25 -> 48535.278 | R25: =+G25+I25+K25+M25+O25 -> 8187.3669 | S25: Giorgio Vignolle
A26: $232100009 | B26: Edoardo Tubia | C26: 457258.06 | D26: 70871.71 | E26: 0.07 | F26: =+C26*E26*0.0444444444444444 -> 1422.5806 | G26: =+F26/G$17 -> 225.44516 | H26: 32274.8 | I26: =+H26/I$8 -> 5732.6465 | J26: =+C26*E26 -> 32008.064 | K26: =+J26/K$8 -> 5969.649 | L26: =+C26*E26 -> 32008.064 | M26: =+L26*M$8 -> 4981.5751 | N26: =+$C26*$E26 -> 32008.064 | O26: =+N26*O$8 -> 4973.2853 | P26: $41112509 | Q26: =+F26+H26+J26+L26+N26 -> 129721.57 | R26: =+G26+I26+K26+M26+O26 -> 21882.601 | S26: Edoardo Tubia
A27: $232100010 | B27: Enrico Tubia | C27: 186635.94 | D27: 28927.23 | E27: 0.07 | F27: =+C27*E27*0.0444444444444444 -> 580.64515 | G27: =+F27/G$17 -> 92.018431 | H27: 13173.39 | I27: =+H27/I$8 -> 2339.8561 | J27: =+C27*E27 -> 13064.516 | K27: =+J27/K$8 -> 2436.5914 | L27: =+C27*E27 -> 13064.516 | M27: =+L27*M$8 -> 2033.2959 | N27: =+$C27*$E27 -> 13064.516 | O27: =+N27*O$8 -> 2029.9123 | P27: $41112510 | Q27: =+F27+H27+J27+L27+N27 -> 52947.583 | R27: =+G27+I27+K27+M27+O27 -> 8931.6742 | S27: Enrico Tubia
A28: $232100011 | B28: Glenelg SA | C28: 622119.82 | D28: 96424.09 | E28: 0.07 | F28: =+C28*E28*0.0444444444444444 -> 1935.4839 | G28: =+F28/G$17 -> 306.72811 | H28: 43911.29 | I28: =+H28/I$8 -> 7799.5187 | J28: =+C28*E28 -> 43548.387 | K28: =+J28/K$8 -> 8121.9716 | L28: =+C28*E28 -> 43548.387 | M28: =+L28*M$8 -> 6777.6533 | N28: =+$C28*$E28 -> 43548.387 | O28: =+N28*O$8 -> 6766.3747 | P28: $41112511 | Q28: =+F28+H28+J28+L28+N28 -> 176491.94 | R28: =+G28+I28+K28+M28+O28 -> 29772.246 | S28: Glenelg SA
C29: =SUM(C18:C28)+0.01 -> 2700000 | D29: =SUM(D18:D28) -> 418480.57 | F29: =SUM(F19:F28) -> 8400 | G29: =SUM(G18:G28) -> 1331.2 | H29: =SUM(H19:H28)-0.02 -> 190575 | I29: =SUM(I18:I28) -> 33849.915 | J29: =SUM(J19:J28) -> 189000 | K29: =SUM(K18:K28) -> 35249.356 | L29: =SUM(L19:L28) -> 189000 | M29: =SUM(M18:M28) -> 29415.015 | N29: =SUM(N19:N28) -> 189000 | O29: =SUM(O18:O28) -> 29366.066 | Q29: =SUM(Q18:Q28) -> 765975.02 | R29: =SUM(R18:R28) -> 129211.55
B32: TOTAL LOAN $232… | C32: =+C11+C29 -> 3289720 | D32: =+D11+D29 -> 548306.88 | F32: =+F11+F29 -> 8400 | G32: =+G11+G29 -> 1331.2 | H32: =+H11+H29 -> 231855.4 | I32: =+I11+I29 -> 41182.135 | J32: =+J11+J29 -> 233170.03 | K32: =+K11+K29 -> 43487.267 | L32: =+L11+L29 -> 236261.93 | M32: =+M11+M29 -> 36770.625 | ... O32: =+O11+O29 -> 35780.05 | Q32: =+Q11+Q29 -> 939967.78 | R32: =+R11+R29 -> 158551.28
B35: TOTAL INTERETS $4111250 | C35: =+F32+H32+J32+L32+N32 -> 939967.76 | D35: =+G32+I32+K32+M32+O32 -> 158551.28
B36: $75541
B42: $4228800 | C42: Créance FRANCO TOSCANO
B43: Date | C43: Montant en EUR | D43: Solde en EUR | E43: Taux d'intérêt
C44: 30000 | D44: =+C44 -> 30000 | E44: 0
B45: 44242 | C45: 100000 | D45: =+D44+C45 -> 130000
B46: 44242 | C46: -100000 | D46: =+D45+C46 -> 30000
B47: 44242 | C47: 29826.31 | D47: =+D46+C47 -> 59826.31
B48: 44242 | C48: -29826.31 | D48: =+D47+C48 -> 30000
B49: 46022 | D49: =+D48+C49 -> 30000
D50: =+D49+C50 -> 30000
D51: =+D50+C51 -> 30000
B52: TOTAL

Sheet CAPITAL
A1: WATERGARDEN MANAGEMENT S.à r.l. | F1: Situation au | G1: 46022
A2: CAPITAL
A6: Date | B6: Nbre actions | C6: Valeur Nominale | D6: Capital social | F6: Date | G6: PRIME DE FUSION
A7: Transfert de Panama vers Luxembourg | F7: FUSION 15/12/2021 EFFET 01/01/21
A8: 40113 | B8: 2125000 | C8: 2 | D8: =+B8*C8 -> 4250000 | F8: 44545 | G8: 1124951.3
A11: TOTAL | D11: =+D8 -> 4250000 | F11: TOTAL | G11: =+G8 -> 1124951.3
A15: 44547 | B15: Franca Cella | C15: 78625 | D15: B | E15: =+C15*2 -> 157250 | F15: =+E15/$E$31 -> 0.037
A16: 44547 | B16: Marylène Alix | C16: 65875 | D16: B | E16: =+C16*2 -> 131750 | F16: =+E16/$E$31 -> 0.031
A17: 44547 | B17: MMM Finance | C17: 106250 | D17: B | E17: =+C17*2 -> 212500 | F17: =+E17/$E$31 -> 0.05
A18: 44547 | B18: Salvatore Desiderio | C18: 176375 | D18: B | E18: =+C18*2 -> 352750 | F18: =+E18/$E$31 -> 0.083
A19: 44547 | B19: Enrico Tubia | C19: 70800 | D19: B | E19: =+C19*2 -> 141600 | F19: =+E19/$E$31 -> 0.033317647
A20: 44547 | B20: Enrico Tubia | C20: 147915 | D20: A | E20: =+C20*2 -> 295830 | F20: =+E20/$E$31 -> 0.069607059 | G20: =+E20/3254150 -> 0.090908532 | H20: =+G20*$G$11 -> 102267.67
A21: 44547 | B21: Alfonso Belardi | C21: 147915 | D21: A | E21: =+C21*2 -> 295830 | F21: =+E21/$E$31 -> 0.069607059 | G21: =+E21/3254150 -> 0.090908532 | H21: =+G21*$G$11 -> 102267.67
A22: 44547 | B22: Stefano Bosi | C22: 147915 | D22: A | E22: =+C22*2 -> 295830 | F22: =+E22/$E$31 -> 0.069607059 | G22: =+E22/3254150 -> 0.090908532 | H22: =+G22*$G$11 -> 102267.67
A23: 44547 | B23: Marco Canton | C23: 147915 | D23: A | E23: =+C23*2 -> 295830 | F23: =+E23/$E$31 -> 0.069607059 | G23: =+E23/3254150 -> 0.090908532 | H23: =+G23*$G$11 -> 102267.67
A24: 44547 | B24: GLENELG SA | C24: 295835 | D24: A | E24: =+C24*2 -> 591670 | F24: =+E24/$E$31 -> 0.13921647 | G24: =+E24/3254150 -> 0.18182014 | H24: =+G24*$G$11 -> 204538.79
A25: 44547 | B25: HEMAWITI Susik | C25: 147915 | D25: A | E25: =+C25*2 -> 295830 | F25: =+E25/$E$31 -> 0.069607059 | G25: =+E25/3254150 -> 0.090908532 | H25: =+G25*$G$11 -> 102267.67
A26: 44547 | B26: JP Murgia | C26: 147915 | D26: A | E26: =+C26*2 -> 295830 | F26: =+E26/$E$31 -> 0.069607059 | G26: =+E26/3254150 -> 0.090908532 | H26: =+G26*$G$11 -> 102267.67
A27: 44547 | B27: Marco Sterzi | C27: 73960 | D27: A | E27: =+C27*2 -> 147920 | F27: =+E27/$E$31 -> 0.034804706 | G27: =+E27/3254150 -> 0.045455803 | H27: =+G27*$G$11 -> 51135.562
A28: 44547 | B28: Edoardo Tubia | C28: 147915 | D28: A | E28: =+C28*2 -> 295830 | F28: =+E28/$E$31 -> 0.069607059 | G28: =+E28/3254150 -> 0.090908532 | H28: =+G28*$G$11 -> 102267.67
A29: 44547 | B29: Sergio Vandi | C29: 147915 | D29: A | E29: =+C29*2 -> 295830 | F29: =+E29/$E$31 -> 0.069607059 | G29: =+E29/3254150 -> 0.090908532 | H29: =+G29*$G$11 -> 102267.67
A30: 44547 | B30: Giorgio Vignolle | C30: 73960 | D30: A | E30: =+C30*2 -> 147920 | F30: =+E30/$E$31 -> 0.034804706 | G30: =+E30/3254150 -> 0.045455803 | H30: =+G30*$G$11 -> 51135.562
C31: =SUM(C15:C30) -> 2125000 | E31: =SUM(E15:E30) -> 4250000 | F31: =SUM(F15:F30) -> 1 | G31: =SUM(G15:G30) -> 1 | H31: =SUM(H15:H30) -> 1124951.3
A36: Date | B36: Nbre actions | C36: Valeur Nominale | D36: Capital social | F36: Date | G36: PRIME D'EMISSION | H36: DETAIL
A37: Augmentation de capital
A38: 44853 | B38: =35466+10854 -> 46320 | C38: 2 | D38: =+B38*C38 -> 92640 | F38: =+A38 -> 44853 | G38: =46320*1.62 -> 75038.4 | H38: 1.62
A41: TOTAL | D41: =+D38 -> 92640 | F41: TOTAL | G41: =+G38 -> 75038.4
A44: Détail de la souscription | I44: Total | J44: Montant libéré
A45: Capital | G45: Prime d'émission
B46: Marco STERZI | C46: 1089 | D46: B | E46: =+C46*2 -> 2178 | F46: =+C46/$B$38 -> 0.023510363 | H46: =C46*1.62 -> 1764.18 | I46: =H46+E46 -> 3942.18 | J46: =3102.34+1422.66-582.82 -> 3942.18 | K46: =J46-I46 -> 0
B47: Adonella STERZI | C47: 1089 | D47: B | E47: =+C47*2 -> 2178 | F47: =+C47/$B$38 -> 0.023510363 | H47: =C47*1.62 -> 1764.18 | I47: =H47+E47 -> 3942.18 | J47: =3102.34+839.84 -> 3942.18 | K47: =J47-I47 -> 0
B48: Marylène ALIX | C48: 1826 | D48: B | E48: =+C48*2 -> 3652 | F48: =+C48/$B$38 -> 0.039421416 | H48: =C48*1.62 -> 2958.12 | I48: =H48+E48 -> 6610.12 | J48: =5198.32+1411.8 -> 6610.12 | K48: =J48-I48 -> 0
B49: Salvatore DESIDERIO | C49: 3845 | D49: B | E49: =+C49*2 -> 7690 | F49: =+C49/$B$38 -> 0.083009499 | H49: =C49*1.62 -> 6228.9 | I49: =H49+E49 -> 13918.9 | J49: 13918.9 | K49: =J49-I49 -> 0
B50: Enrico TUBIA | C50: 3005 | D50: B | E50: =+C50*2 -> 6010 | F50: =+C50/$B$38 -> 0.064874784 | H50: =C50*1.62 -> 4868.1 | I50: =H50+E50 -> 10878.1 | J50: =11670.88-792.78 -> 10878.1 | K50: =J50-I50 -> 0
B51: Enrico TUBIA | C51: 3546 | D51: A | E51: =+C51*2 -> 7092 | F51: =+C51/$B$38 -> 0.076554404 | H51: =C51*1.62 -> 5744.52 | I51: =H51+E51 -> 12836.52 | J51: =5585.66+5292.44+1165.64+792.78 -> 12836.52 | K51: =J51-I51 -> 0
B52: Alfonso BELARDI | C52: 3546 | D52: A | E52: =+C52*2 -> 7092 | F52: =+C52/$B$38 -> 0.076554404 | H52: =C52*1.62 -> 5744.52 | I52: =H52+E52 -> 12836.52 | J52: =11670.88+1165.64 -> 12836.52 | K52: =J52-I52 -> 0
B53: Stefano BOSI | C53: 3546 | D53: A | E53: =+C53*2 -> 7092 | F53: =+C53/$B$38 -> 0.076554404 | H53: =C53*1.62 -> 5744.52 | I53: =H53+E53 -> 12836.52 | J53: =11670.88+1165.64 -> 12836.52 | K53: =J53-I53 -> 0
B54: Marco CANTON | C54: 3546 | D54: A | E54: =+C54*2 -> 7092 | F54: =+C54/$B$38 -> 0.076554404 | H54: =C54*1.62 -> 5744.52 | I54: =H54+E54 -> 12836.52 | J54: =11670.88+1165.64 -> 12836.52 | K54: =J54-I54 -> 0
B55: GLENELG S.A. | C55: 7098 | D55: A | E55: =+C55*2 -> 14196 | F55: =+C55/$B$38 -> 0.15323834 | H55: =C55*1.62 -> 11498.76 | I55: =H55+E55 -> 25694.76 | J55: =23349+2345.76 -> 25694.76 | K55: =J55-I55 -> 0
B56: J.P. MURGIA | C56: 3546 | D56: A | E56: =+C56*2 -> 7092 | F56: =+C56/$B$38 -> 0.076554404 | H56: =C56*1.62 -> 5744.52 | I56: =H56+E56 -> 12836.52 | J56: =1165.64+11670.88 -> 12836.52 | K56: =J56-I56 -> 0
...

Sheet LOAN OUT
A1: WATERGARDEN MANAGEMENT S.à r.l. | F1: Situation au | G1: 46022
A2: FINANCEMENTS RECUS
A6: SHAREHOLDERS LOAN | B6: SOLDE COMPTE $4522 | C6: SPLIT PART ARCO IRIS 2.700.000 EUR | D6: SPLIT PART ARCO IRIS 589.720 EUR | F6: PREMIUM 70% INT ARCO IRIS FOR 2022 | G6: PREMIUM 70% INT ARCO IRIS FOR 2023 | H6: PREMIUM 70% INT ARCO IRIS FOR 2024 | I6: PREMIUM 70% INT ARCO IRIS FOR 2025
A7: Alfonso Belardi | B7: 19170 | C7: 0 | D7: 0 | F7: =+'LOAN ARCO IRIS'!I18*70% -> 0 | G7: =+'LOAN ARCO IRIS'!K18*70% -> 0 | H7: =+'LOAN ARCO IRIS'!M18*70% -> 0 | I7: =+'LOAN ARCO IRIS'!N18*70% -> 0 | K7: =SUM(F7:J7) -> 0
A8: Sergio Vandi | B8: =69170-C8 -> 20957.95 | C8: 48212.05 | D8: 0 | F8: =+'LOAN ARCO IRIS'!I19*70% -> 2729.8321 | G8: =+'LOAN ARCO IRIS'!K19*70% -> 2842.6901 | H8: =+'LOAN ARCO IRIS'!M19*70% -> 2372.1786 | I8: =+'LOAN ARCO IRIS'!O19*70% -> 2368.2311 | K8: =SUM(F8:J8) -> 10312.932 | L8: $452180001
A9: Jean-Pierre Murgia | B9: =22670-C9 -> 19295.16 | C9: 3374.84 | D9: 0 | F9: =+'LOAN ARCO IRIS'!I20*70% -> 191.08881 | G9: =+'LOAN ARCO IRIS'!K20*70% -> 198.98827 | H9: =+'LOAN ARCO IRIS'!M20*70% -> 166.05248 | I9: =+'LOAN ARCO IRIS'!O20*70% -> 165.77615 | K9: =SUM(F9:J9) -> 721.90571 | L9: $452180002
A10: Stéphane Bosi | B10: =59170-C10 -> 20600.36 | C10: 38569.64 | D10: 0 | F10: =+'LOAN ARCO IRIS'!I21*70% -> 2183.8657 | G10: =+'LOAN ARCO IRIS'!K21*70% -> 2274.1521 | H10: =+'LOAN ARCO IRIS'!M21*70% -> 1897.7429 | I10: =+'LOAN ARCO IRIS'!O21*70% -> 1894.5849 | K10: =SUM(F10:J10) -> 8250.3456 | L10: $452180003
A11: Marco Canton | B11: =49170-C11 -> 20242.77 | C11: 28927.23 | D11: 0 | F11: =+'LOAN ARCO IRIS'!I22*70% -> 1637.8993 | G11: =+'LOAN ARCO IRIS'!K22*70% -> 1705.614 | H11: =+'LOAN ARCO IRIS'!M22*70% -> 1423.3071 | I11: =+'LOAN ARCO IRIS'!O22*70% -> 1420.9386 | K11: =SUM(F11:J11) -> 6187.7591 | L11: $452180004
A12: Susik Hemawiti | B12: =30670-C12 -> 19581.23 | C12: 11088.77 | D12: 0 | F12: =+'LOAN ARCO IRIS'!I23*70% -> 627.86146 | G12: =+'LOAN ARCO IRIS'!K23*70% -> 653.81872 | H12: =+'LOAN ARCO IRIS'!M23*70% -> 545.60109 | I12: =+'LOAN ARCO IRIS'!O23*70% -> 544.69317 | K12: =SUM(F12:J12) -> 2371.9744 | L12: $452180005
A13: Marco Sterzi | B13: =77580-C13 -> 12011.62 | C13: 65568.38 | D13: 0 | F13: =+'LOAN ARCO IRIS'!I24*70% -> 3712.5712 | G13: =+'LOAN ARCO IRIS'!K24*70% -> 3866.0584 | H13: =+'LOAN ARCO IRIS'!M24*70% -> 3226.1629 | I13: =+'LOAN ARCO IRIS'!O24*70% -> 3220.7943 | K13: =SUM(F13:J13) -> 14025.587 | L13: $452180006
A14: Giorgio Vignolle | B14: =66906.31-C14-D14 -> 10563.37 | C14: 26516.63 | D14: 29826.31 | F14: =+'LOAN ARCO IRIS'!I25*70%+'LOAN ARCO IRIS'!I9*70% -> 2680.5599 | G14: =+'LOAN ARCO IRIS'!K25*70%+'LOAN ARCO IRIS'!K9*70% -> 2888.2848 | H14: =+'LOAN ARCO IRIS'!M25*70%+'LOAN ARCO IRIS'!M9*70% -> 2487.6133 | I14: =+'LOAN ARCO IRIS'!O25*70%+'LOAN ARCO IRIS'!O9*70% -> 2334.0116 | K14: =SUM(F14:J14) -> 10390.47 | L14: $452180007
A15: Edoardo Tubia | B15: =192670-C15-D15 -> 21798.29 | C15: 70871.71 | D15: 100000 | F15: =+'LOAN ARCO IRIS'!I26*70%+'LOAN ARCO IRIS'!I10*70% -> 7966.2536 | G15: =+'LOAN ARCO IRIS'!K26*70%+'LOAN ARCO IRIS'!K10*70% -> 8620.4866 | H15: =+'LOAN ARCO IRIS'!M26*70%+'LOAN ARCO IRIS'!M10*70% -> 7453.1149 | I15: =+'LOAN ARCO IRIS'!O26*70%+'LOAN ARCO IRIS'!O10*70% -> 6939.6039 | K15: =SUM(F15:J15) -> 30979.459 | L15: $452180008
A16: Enrico Tubia | B16: =49170-C16 -> 20242.77 | C16: 28927.23 | D16: 0 | F16: =+'LOAN ARCO IRIS'!I27*70% -> 1637.8993 | G16: =+'LOAN ARCO IRIS'!K27*70% -> 1705.614 | H16: =+'LOAN ARCO IRIS'!M27*70% -> 1423.3071 | I16: =+'LOAN ARCO IRIS'!O27*70% -> 1420.9386 | K16: =SUM(F16:J16) -> 6187.7591 | L16: $452180009
A17: GLENELG SA | B17: =138330-C17 -> 41905.91 | C17: 96424.09 | D17: 0 | F17: =+'LOAN ARCO IRIS'!I28*70% -> 5459.6631 | G17: =+'LOAN ARCO IRIS'!K28*70% -> 5685.3801 | H17: =+'LOAN ARCO IRIS'!M28*70% -> 4744.3573 | I17: =+'LOAN ARCO IRIS'!O28*70% -> 4736.4623 | K17: =SUM(F17:J17) -> 20625.863 | L17: $452180010
A18: =SUM(B18:D18) -> 774676.31 | B18: =SUM(B7:B17) -> 226369.43 | C18: =SUM(C7:C17) -> 418480.57 | D18: =SUM(D7:D17) -> 129826.31 | F18: =SUM(F7:F17) -> 28827.494 | G18: =SUM(G7:G17) -> 30441.087 | H18: =SUM(H7:H17) -> 25739.438 | I18: =SUM(I7:I17) -> 25046.035 | K18: =SUM(K7:K17) -> 110054.05 | L18: $65542
A21: $45128 dette Arco Iris - augm cap à payer | B21: DETTE BRL | C21: DETTE EUR
A22: 44931 | B22: 500000 | C22: 87627.06 | D22: augm capital pour compte de Watergarden (tx de change système comptable = BCE)
A23: 44931 | B23: -489151.72 | C23: -85725.85 | D23: paiement partiel par F Toscano (tx de change système comptable = BCE)
A24: 45291 | C24: 122.04 | D24: réval 31/12/23 - perte de change non réalisée
B25: =SUM(B22:B24) -> 10848.28 | C25: =SUM(C22:C24) -> 2023.25

Sheet RES REP
A2: PERTES REPORTABLES | B2: 2019 | C2: -2422.37
B3: 2020 | C3: -6590.61
B4: 2021 | C4: -15174.44
B5: 2022 | C5: 0
B6: 2023 | C6: 0
B7: 2024 | C7: -57586.88
A9: TOTAL | C9: =SUM(C2:C8) -> -81774.3
